
  0%|          | 0/500 [00:45<?, ?it/s]
Traceback (most recent call last):
  File "/home/baris/.local/lib/python3.10/site-packages/monai/transforms/transform.py", line 91, in apply_transform
    return _apply_transform(transform, data, unpack_items)
  File "/home/baris/.local/lib/python3.10/site-packages/monai/transforms/transform.py", line 55, in _apply_transform
    return transform(parameters)
  File "/home/baris/Documents/uni/AAAsegmentor/src/data/custom_transforms.py", line 17, in __call__
    img, img_meta = reader.get_data(reader.read(img))
  File "/home/baris/.local/lib/python3.10/site-packages/monai/data/image_reader.py", line 267, in read
    img_.append(itk.imread(name, **kwargs_))
  File "/home/baris/.local/lib/python3.10/site-packages/itk/support/extras.py", line 1293, in imread
    reader = template_reader_type.New(**kwargs)
  File "/home/baris/.local/lib/python3.10/site-packages/itk/support/template_class.py", line 661, in New
    return self._NewImageReader(
  File "/home/baris/.local/lib/python3.10/site-packages/itk/support/template_class.py", line 160, in _NewImageReader
    raise RuntimeError(
RuntimeError: Could not create IO object for reading file /data/AAA/images/EL_110pre.mhd
The file doesn't exist.
Filename = /data/AAA/images/EL_110pre.mhd
The above exception was the direct cause of the following exception:
Traceback (most recent call last):
  File "/home/baris/.local/lib/python3.10/site-packages/monai/transforms/transform.py", line 91, in apply_transform
    return _apply_transform(transform, data, unpack_items)
  File "/home/baris/.local/lib/python3.10/site-packages/monai/transforms/transform.py", line 55, in _apply_transform
    return transform(parameters)
  File "/home/baris/.local/lib/python3.10/site-packages/monai/transforms/compose.py", line 173, in __call__
    input_ = apply_transform(_transform, input_, self.map_items, self.unpack_items, self.log_stats)
  File "/home/baris/.local/lib/python3.10/site-packages/monai/transforms/transform.py", line 118, in apply_transform
    raise RuntimeError(f"applying transform {transform}") from e
RuntimeError: applying transform <src.data.custom_transforms.LoadMHD object at 0x7fc887393c10>
The above exception was the direct cause of the following exception:
Traceback (most recent call last):
  File "/home/baris/Documents/uni/AAAsegmentor/src/main.py", line 36, in <module>
    main()
  File "/home/baris/Documents/uni/AAAsegmentor/src/main.py", line 31, in main
    test_loss = test_single_epoch(model=model, test_loader=test_loader)
  File "/home/baris/Documents/uni/AAAsegmentor/src/training/test.py", line 17, in test_single_epoch
    for d in test_loader:
  File "/home/baris/.local/lib/python3.10/site-packages/torch/utils/data/dataloader.py", line 681, in __next__
    data = self._next_data()
  File "/home/baris/.local/lib/python3.10/site-packages/torch/utils/data/dataloader.py", line 721, in _next_data
    data = self._dataset_fetcher.fetch(index)  # may raise StopIteration
  File "/home/baris/.local/lib/python3.10/site-packages/torch/utils/data/_utils/fetch.py", line 49, in fetch
    data = [self.dataset[idx] for idx in possibly_batched_index]
  File "/home/baris/.local/lib/python3.10/site-packages/torch/utils/data/_utils/fetch.py", line 49, in <listcomp>
    data = [self.dataset[idx] for idx in possibly_batched_index]
  File "/home/baris/.local/lib/python3.10/site-packages/monai/data/dataset.py", line 105, in __getitem__
    return self._transform(index)
  File "/home/baris/.local/lib/python3.10/site-packages/monai/data/dataset.py", line 878, in _transform
    data = apply_transform(_transform, data)
  File "/home/baris/.local/lib/python3.10/site-packages/monai/transforms/transform.py", line 118, in apply_transform
    raise RuntimeError(f"applying transform {transform}") from e
RuntimeError: applying transform <monai.transforms.compose.Compose object at 0x7fc886f20220>
Traceback (most recent call last):
  File "/home/baris/.local/lib/python3.10/site-packages/monai/transforms/transform.py", line 91, in apply_transform
    return _apply_transform(transform, data, unpack_items)
  File "/home/baris/.local/lib/python3.10/site-packages/monai/transforms/transform.py", line 55, in _apply_transform
    return transform(parameters)
  File "/home/baris/Documents/uni/AAAsegmentor/src/data/custom_transforms.py", line 17, in __call__
    img, img_meta = reader.get_data(reader.read(img))
  File "/home/baris/.local/lib/python3.10/site-packages/monai/data/image_reader.py", line 267, in read
    img_.append(itk.imread(name, **kwargs_))
  File "/home/baris/.local/lib/python3.10/site-packages/itk/support/extras.py", line 1293, in imread
    reader = template_reader_type.New(**kwargs)
  File "/home/baris/.local/lib/python3.10/site-packages/itk/support/template_class.py", line 661, in New
    return self._NewImageReader(
  File "/home/baris/.local/lib/python3.10/site-packages/itk/support/template_class.py", line 160, in _NewImageReader
    raise RuntimeError(
RuntimeError: Could not create IO object for reading file /data/AAA/images/EL_110pre.mhd
The file doesn't exist.
Filename = /data/AAA/images/EL_110pre.mhd
The above exception was the direct cause of the following exception:
Traceback (most recent call last):
  File "/home/baris/.local/lib/python3.10/site-packages/monai/transforms/transform.py", line 91, in apply_transform
    return _apply_transform(transform, data, unpack_items)
  File "/home/baris/.local/lib/python3.10/site-packages/monai/transforms/transform.py", line 55, in _apply_transform
    return transform(parameters)
  File "/home/baris/.local/lib/python3.10/site-packages/monai/transforms/compose.py", line 173, in __call__
    input_ = apply_transform(_transform, input_, self.map_items, self.unpack_items, self.log_stats)
  File "/home/baris/.local/lib/python3.10/site-packages/monai/transforms/transform.py", line 118, in apply_transform
    raise RuntimeError(f"applying transform {transform}") from e
RuntimeError: applying transform <src.data.custom_transforms.LoadMHD object at 0x7fc887393c10>
The above exception was the direct cause of the following exception:
Traceback (most recent call last):
  File "/home/baris/Documents/uni/AAAsegmentor/src/main.py", line 36, in <module>
    main()
  File "/home/baris/Documents/uni/AAAsegmentor/src/main.py", line 31, in main
    test_loss = test_single_epoch(model=model, test_loader=test_loader)
  File "/home/baris/Documents/uni/AAAsegmentor/src/training/test.py", line 17, in test_single_epoch
    for d in test_loader:
  File "/home/baris/.local/lib/python3.10/site-packages/torch/utils/data/dataloader.py", line 681, in __next__
    data = self._next_data()
  File "/home/baris/.local/lib/python3.10/site-packages/torch/utils/data/dataloader.py", line 721, in _next_data
    data = self._dataset_fetcher.fetch(index)  # may raise StopIteration
  File "/home/baris/.local/lib/python3.10/site-packages/torch/utils/data/_utils/fetch.py", line 49, in fetch
    data = [self.dataset[idx] for idx in possibly_batched_index]
  File "/home/baris/.local/lib/python3.10/site-packages/torch/utils/data/_utils/fetch.py", line 49, in <listcomp>
    data = [self.dataset[idx] for idx in possibly_batched_index]
  File "/home/baris/.local/lib/python3.10/site-packages/monai/data/dataset.py", line 105, in __getitem__
    return self._transform(index)
  File "/home/baris/.local/lib/python3.10/site-packages/monai/data/dataset.py", line 878, in _transform
    data = apply_transform(_transform, data)
  File "/home/baris/.local/lib/python3.10/site-packages/monai/transforms/transform.py", line 118, in apply_transform
    raise RuntimeError(f"applying transform {transform}") from e
RuntimeError: applying transform <monai.transforms.compose.Compose object at 0x7fc886f20220>